<mujoco model="rat">
  <asset>
    <texture type="skybox" builtin="gradient" rgb1=".3 .5 .7" rgb2="0 0 0" width="32" height="512"/>
    <texture name="body" type="cube" builtin="flat" mark="cross" width="128" height="128" rgb1="0.8 0.6 0.4" rgb2="0.8 0.6 0.4" markrgb="1 1 1" random="0.01"/>
    <material name="body" texture="body" texuniform="true" rgba="0.8 0.6 .4 1"/>
    <texture name="grid" type="2d" builtin="checker" width="512" height="512" rgb1=".1 .2 .3" rgb2=".2 .3 .4"/>
    <material name="grid" texture="grid" texrepeat="1 1" texuniform="true" reflectance=".2"/>
  </asset>
  <compiler angle="radian"/>
  <size njmax="8000" nconmax="4000"/>
  <default class="body">
    <joint limited="true" solreflimit="0.01 1" solimplimit="0.99 0.9999 0" armature="6e-07" damping="0.001"/>
    <geom friction="0.7 0.005 0.0001" solref="0.005 1"/>
    <site group="3" rgba="0 0 1 1"/>
    <general ctrllimited="true" ctrlrange="-1 1" forcelimited="false" gainprm="0.01"/>
    <default class="bone">
      <geom contype="0" conaffinity="0" group="0" rgba="0.5 0.5 0.5 1" density="1100.0"/>
    </default>
    <default class="lumbar">
      <joint group="3" pos="0.003 0 -0.003" armature="1e-05" damping="0.03"/>
      <general gainprm="0.15"/>
      <default class="lumbar_extend">
        <joint stiffness="0.02" range="-0.5235987755982988 0.7853981633974483"/>
        <general gainprm="0.4"/>
      </default>
      <default class="lumbar_bend">
        <joint stiffness="0.03" range="-0.5235987755982988 0.5235987755982988"/>
      </default>
      <default class="lumbar_twist">
        <joint stiffness="0.03" range="-0.5235987755982988 0.5235987755982988"/>
      </default>
    </default>
    <default class="cervical">
      <joint group="3" pos="-0.02 0 -0.05" stiffness="1.0" armature="0.001" damping="1.0"/>
      <default class="cervical_extend">
        <joint range="-0.4072434921320102 0.6108652381980153"/>
        <general gainprm="2.5"/>
      </default>
      <default class="cervical_bend">
        <joint range="-0.6108652381980153 0.6108652381980153"/>
        <general gainprm="2.5"/>
      </default>
      <default class="cervical_twist">
        <joint range="-0.6108652381980153 0.6108652381980153"/>
        <general gainprm="2.5"/>
      </default>
    </default>
    <default class="atlas">
      <joint axis="0 -1 0" stiffness="0.002" range="-0.08726646259971647 0.7853981633974483" damping="0.002"/>
      <general gainprm="0.025"/>
    </default>
    <default class="mandible">
      <joint stiffness="0.002" range="-0.296705972839036 0.2617993877991494" springref="-0.314159265359" damping="0.002"/>
      <general gainprm="0.025"/>
    </default>
    <default class="caudal">
      <joint group="3" stiffness="1e-05" damping="0.002"/>
      <general gainprm="0.005"/>
      <default class="caudal_extend">
        <joint range="-0.08726646259971647 0.08726646259971647"/>
      </default>
      <default class="caudal_bend">
        <joint range="-0.08726646259971647 0.08726646259971647"/>
      </default>
    </default>
    <default class="hip">
      <joint armature="1e-05" damping="0.02"/>
      <general gainprm="0.2"/>
      <default class="hip_supinate">
        <joint range="-0.6981317007977318 0.5235987755982988"/>
      </default>
      <default class="hip_abduct">
        <joint range="-0.5235987755982988 1.047197551196598"/>
      </default>
      <default class="hip_extend">
        <joint range="-1.570796326794897 1.047197551196598"/>
        <general gainprm="0.3"/>
      </default>
    </default>
    <default class="knee">
      <joint range="-1.221730476396031 1.53588974175501" damping="0.005"/>
      <general gainprm="0.2"/>
    </default>
    <default class="ankle">
      <joint range="-0.1396263401595464 1.396263401595464" damping="0.003"/>
      <general gainprm="0.2"/>
    </default>
    <default class="toe">
      <joint range="0 0.8726646259971648" damping="0.001"/>
      <general gainprm="0.025"/>
    </default>
    <default class="scapula">
      <joint damping="0.005" solimplimit="0 .99 .01"/>
      <default class="scapula_supinate">
        <joint pos="0 0.005000000000000001 0" range="-0.0174532925199433 0.1745329251994329"/>
      </default>
      <default class="scapula_abduct">
        <joint pos="0 0.005000000000000001 -0.01" range="-0.2617993877991494 0.2617993877991494"/>
      </default>
      <default class="scapula_extend">
        <joint pos="0 0 0" range="-0.03490658503988659 0.03490658503988659"/>
        <general gainprm="0.25"/>
      </default>
    </default>
    <default class="shoulder">
      <joint range="-1.308996938995747 0.8726646259971648" damping="0.005" solimplimit="0 .99 .01"/>
      <general gainprm="0.15"/>
    </default>
    <default class="shoulder_sup">
      <joint range="-0.05235987755982989 1.134464013796314" damping="0.005" solimplimit="0 .99 .01"/>
      <general gainprm="0.15"/>
    </default>
    <default class="elbow">
      <joint range="-1.308996938995747 0.6981317007977318" damping="0.003"/>
      <general gainprm="0.15"/>
    </default>
    <default class="wrist">
      <joint range="-0.3490658503988659 2.094395102393195" damping="0.002"/>
      <general gainprm="0.05"/>
    </default>
    <default class="finger">
      <joint range="0 1.570796326794897" damping="0.002"/>
      <general gainprm="0.025"/>
    </default>
    <default class="sensor">
      <site group="4"/>
    </default>
    <default class="tracking_site">
      <site type="sphere" size="0.027" rgba="1 0 0 1" group="3"/>
    </default>
  </default>
  <visual>
    <quality shadowsize="2048"/>
  </visual>
  <statistic meansize="0.003"/>
  <worldbody>
    <geom name="floor" size="0 0 .1" type="plane" material="grid" condim="3"/>
    <body name="torso" pos="0.03099526054578288 2.058524937651458e-07 1" childclass="body">
      <freejoint name="root"/>
      <site name="tracking[torso]" class="tracking_site" />
      <light name="tracking_light" mode="trackcom" pos="0 0 3"/>
      <camera name="back" mode="trackcom" pos="-1 0 0.5" xyaxes="0 -1 0 1 0 2"/>
      <camera name="side" mode="trackcom" pos="0 -1 0.5" xyaxes="1 0 0 0 1 2"/>
      <camera name="side_alt" mode="trackcom" pos="0.5 -0.561 0.199" xyaxes="0.766 0.643 0.000 -0.162 0.192 0.968"/>
      <camera name="top" mode="trackcom" fovy="100.0" pos="0 0 1" zaxis="0 -0.2 1"/>
      <geom name="collision_torso"  type="sphere" size="0.035" density="468.251260009" pos="-0.008200000000000001 0 0" euler="0 0.1745329251994329 0"/>

      <body name="scapula_R" pos="0.00656 -0.00164 0.01148">
        <site name="tracking[scapula_R]" class="tracking_site" />
        <joint name="scapula_R_supinate" class="scapula_supinate" pos="0 0.005000000000000001 0" axis="0 0 -1" type="hinge" stiffness="1" limited="true"/>
        <joint name="scapula_R_abduct" class="scapula_abduct" pos="0 0.005000000000000001 -0.01" axis="-1 0 0"/>
        <joint name="scapula_R_extend" class="scapula_extend" pos="0 0 0" axis="-0.3 1 0"/> -->
        <site name="shoulder_R" size="0.002" pos="0.0287 -0.00984 -0.02542"/>
        <geom name="scapula_R_collision"  type="sphere" size="0.005005370266735553 0.01463183127343655 0.02431103959679604" density="513.564646393" pos="0.01757062018850453 -0.008637295267367218 -0.01522952062810994" quat="0.3867556972129688 0.4740321312040688 0.7692223496423682 0.1844194839763772"/>
        <body name="upper_arm_R" pos="0.0287 -0.00984 -0.02542">
          <site name="tracking[upper_arm_R]" class="tracking_site" />
          <joint name="shoulder_R" class="shoulder" axis="0 1 0"/>
          <joint name="shoulder_sup_R" class="shoulder_sup" axis="-0 -0 1"/>
          <site name="elbow_R" type="cylinder" size="0.0006000000000000001 0.004" pos="-0.01593120836133218 -0.01035528543486592 -0.02230369170586505" zaxis="0 1 -0.2"/>
          <geom name="humerus_R_collision"  size="0.007771321151869356 0.01554264230373871" pos="-0.007743341889514446 -0.005788347560550173 -0.01198335067124012" quat="0.8109593935310486 0.0007013948082913995 0.3450082795040448 0.4725607444157158"/>
        </body>
      </body>
    </body>
  </worldbody>
  <contact>
    <pair geom1="collision_torso" geom2="floor"/>
    <pair geom1="scapula_R_collision" geom2="floor"/>
    <!-- <pair geom1="humerus_R_collision" geom2="floor"/> -->
  </contact>
  <actuator>
  </actuator>
  <compiler meshdir="./"/>
</mujoco>

