<mujoco>
  <option timestep=".001">
    <!-- <flag energy="enable" contact="disable"/> -->
  </option>

  <default>
    <joint type="hinge" axis="0 -1 0"/>
    <geom type="capsule" size=".02"/>
  </default>

  <worldbody>
    <light pos="0 -.4 1"/>
    <camera name="fixed" pos="0 -1 0" xyaxes="1 0 0 0 0 1"/>
    <body name="base" pos="0 0 .2">
      <joint name="root"/>
      <geom fromto="0 0 0 0 0 -.25" rgba="1 1 0 1"/>
      <!-- <body name="3" pos="0 0 -.25">
         <joint/>
         <geom fromto="0 0 0 0 0 -.2" rgba="0 0 1 1"/>
      </body> -->
    </body>
  </worldbody>
</mujoco>